<pre>--- Summary ---
Tests passed: 0 out of 4

--- Details ---
Test #0: failed 
Test case description: ML4T-220
Traceback:
  File "grade_strategy_learner.py", line 443, in test_strategy
    raise IncorrectOutput(
IncorrectOutput: Test failed on one or more output criteria.
  Inputs:
    insample_args: {'symbol': 'ML4T-220', 'sd': datetime.datetime(2008, 1, 1, 0, 0), 'ed': datetime.datetime(2009, 12, 31, 0, 0), 'sv': 100000}
    outsample_args: {'symbol': 'ML4T-220', 'sd': datetime.datetime(2010, 1, 1, 0, 0), 'ed': datetime.datetime(2011, 12, 31, 0, 0), 'sv': 100000}
    benchmark_type: clean
    benchmark: 1.0
    train_time: 25
    test_time: 5
    max_time: 60
    seed: 1481090000

  Failures:
  in-sample return (0.23052150000000027) did not beat benchmark (1.0)
  out-sample return (0.1637626400000003) did not beat benchmark (1.0)

Test #1: failed 
Test case description: AAPL
Traceback:
  File "grade_strategy_learner.py", line 387, in test_strategy
    student_outsample_cr = eval_policy_2(
  File "grade_strategy_learner.py", line 516, in eval_policy_2
    portvals = compute_portvals(
  File "grade_strategy_learner.py", line 555, in compute_portvals
    price = prices[symbol][date]
  File "series.py", line 958, in __getitem__
    return self._get_value(key)
  File "series.py", line 1069, in _get_value
    loc = self.index.get_loc(label)
  File "datetimes.py", line 681, in get_loc
    raise KeyError(orig_key) from err
KeyError: Timestamp('2010-01-02 00:00:00')

Test #2: failed 
Test case description: SINE_FAST_NOISE
Traceback:
  File "grade_strategy_learner.py", line 387, in test_strategy
    student_outsample_cr = eval_policy_2(
  File "grade_strategy_learner.py", line 516, in eval_policy_2
    portvals = compute_portvals(
  File "grade_strategy_learner.py", line 555, in compute_portvals
    price = prices[symbol][date]
  File "series.py", line 958, in __getitem__
    return self._get_value(key)
  File "series.py", line 1069, in _get_value
    loc = self.index.get_loc(label)
  File "datetimes.py", line 681, in get_loc
    raise KeyError(orig_key) from err
KeyError: Timestamp('2010-01-02 00:00:00')

Test #3: failed 
Test case description: UNH - In sample
Traceback:
  File "grade_strategy_learner.py", line 387, in test_strategy
    student_outsample_cr = eval_policy_2(
  File "grade_strategy_learner.py", line 516, in eval_policy_2
    portvals = compute_portvals(
  File "grade_strategy_learner.py", line 555, in compute_portvals
    price = prices[symbol][date]
  File "series.py", line 958, in __getitem__
    return self._get_value(key)
  File "series.py", line 1069, in _get_value
    loc = self.index.get_loc(label)
  File "datetimes.py", line 681, in get_loc
    raise KeyError(orig_key) from err
KeyError: Timestamp('2010-01-02 00:00:00')

</pre>
